Workbook
Name ColumnTitle..P44: #REF!
Name ColumnTitle..P44: #REF!
Name dd: #REF!
Name dd: #REF!
Name de: #REF!
Name de: #REF!
Name means: #REF!
Name means: #REF!
Name Numbers: #REF!
Name Numbers: #REF!
Name SASOutput: #REF!
Name SASOutput: #REF!
Name Table1: #REF!
Name Table1: #REF!
Name Table1a: '1 Prov territorial profile'!$A$10:$D$49
Name Table1b: '1 Prov territorial profile'!$A$50:$D$56
Name Table1b: '1 Prov territorial profile'!$A$50:$D$56
Name Table2: '2 Supply'!$A$11:$G$21
Name Table3: '3 Inflow and outflow'!$A$10:$E$20
Name Table3: #REF!
Name Table3: #REF!
Name Table4: '4 Workforce'!$A$11:$G$21
Name Table5a: '5 Direct care'!$A$11:$C$16
Name Table5b: '5 Direct care'!$A$18:$C$23
Name Table6: '6 New graduate migrations'!$A$10:$D$23
Name Table7a: '7 Hospital Staffing indicators'!$A$11:$H$16
Name Table7b: '7 Hospital Staffing indicators'!$A$18:$H$23
Name Table7c: '7 Hospital Staffing indicators'!$A$25:$H$30
Name Table7d: '7 Hospital Staffing indicators'!$A$32:$H$37
Name Table7e: '7 Hospital Staffing indicators'!$A$39:$H$44
Name Table7f: '7 Hospital Staffing indicators'!$A$46:$H$51
Name Table7g: '7 Hospital Staffing indicators'!$A$53:$H$58
Name Table8a: '8 Vacancy metrics'!$A$11:$D$20
Name Table8b: '8 Vacancy metrics'!$A$35:$C$43
Name TABLEX: #REF!
Name TABLEX: #REF!
Name tablexy: #REF!
Name tablexy: #REF!
Name Title..AE156: #REF!
Name Title..AE156: #REF!
Name Title..AE177: #REF!
Name Title..AE177: #REF!
Name Title..AF143: #REF!
Name Title..AF143: #REF!
Name Title..AL116: #REF!
Name Title..AL116: #REF!
Name Title..BI156: #REF!
Name Title..BI156: #REF!
Name Title..BI183: #REF!
Name Title..BI183: #REF!
Name Title..BJ143: #REF!
Name Title..BJ143: #REF!
Name Title..D33: #REF!
Name Title..D33: #REF!
Name Title..D55: #REF!
Name Title..D62: #REF!
Name Title..E24: #REF!
Name Title..E44: #REF!
Name Title..E44: #REF!
Name Title..E74: #REF!

Sheet Instructions
A1: This workbook has 15 worksheets, including this title page, a table of contents on tab 2, figures and data tables on tabs 3 to 10, notes and terminology on tabs 11 to 14, and contact information on tab 15. Notes and sources can be found after the data tables in column A.
A2: Instructions The following Unicode symbols are used in this workbook (these symbols may need to be enabled if using screen reading software): em dash (—) asterisk (*) dagger (†) caret (^) Instructions are provided in each tab where there are interactive drop-down lists on how to operate them.
A3: Health Workforce in Canada, 2023 — Quick Stats (Updated June 2025)
A4: The collection and reporting of health workforce data assists decision-makers in the planning and distribution of health care professionals.
A5: Health Workforce in Canada, 2023 — Quick Stats contains data on the supply, workforce, inflow/outflow and provincial and territorial trends of Canada’s health workforce in the Quick Stats tool. The file currently contains information on physicians, regulated nurses, physiotherapists, occupational therapists and pharmacists.
A6: This Quick Stats file provides 8 interactive data tables to facilitate research and analysis, including by profession; by demographic, education and employment data elements, including vacancies; and by selected hospital staffing indicators.
A7: Unless otherwise indicated, this product uses data from the following CIHI databases: Health Workforce Database, with data provided by provincial and territorial regulatory bodies; Scott’s Medical Database, with raw data provided by iMD (© 2023 iMD Health Global Corp.); and Canadian MIS Database, with data provided by provincial ministries and departments of health; or from Statistics Canada’s Job Vacancy and Wage Survey.
A8: Additional resources
A9: The following health workforce products are available on CIHI’s website:
A10: • The state of the health workforce in Canada, 2023 (digital report)
A11: • Nursing in Canada, 2023 (data tables, methodology notes)
A12: • Occupational Therapists in Canada, 2023 (data tables, methodology notes)
... A22: End of worksheet (go to Table of contents)

Sheet Table of contents
A1: Table of contents
A2: Table 1 Provincial/territorial profile of providers, by selected type, place of work, province/territory and data year (with figures)
A3: Table 2 Supply of providers, by selected type and province/territory, 2014 to 2023 (with figures)
A4: Table 3 Inflow and outflow of providers, by selected type and province/territory, 2014 to 2023 (with figure)
A5: Table 4 Workforce of providers, by selected type and province/territory, 2014 to 2023 (with figures)
A6: Tables 5a and 5b Providers working in direct care by selected type and province/territory, 2019 to 2023 (with figures)
A7: Table 6 Migration of recent health professional graduates: Province/territory in 2023, by selected province/territory of graduation (with figure)
A8: Tables 7a to 7g Selected Hospital Staffing indicators, by hospital service area and province/territory, 2019–2020 to 2023–2024 (with figures)
A9: Tables 8a and 8b Vacancy metrics, by National Occupation Code (NOC) occupation and province/territory, 2015 to 2023 (with figures)
A10: Notes to readers
A11: Terminology
A12: Notes on selected Hospital Staffing indicators
... A15: End of worksheet

Sheet 1 Prov territorial profile
A1: This tab provides the provincial or territorial profile for different types of providers for a given place of work and year. The figures and table will populate information based on your selections. Select the type of provider in cell A6. Select the province or territory in cell B6. Select the place of work in cell C6. Select the year in cell D6. The table begins at cell A10 and ends at D56. The notes and sources begin in cell A57 and end in cell A99. There are 8 figures in cell A8: Sex, Age Group, Country of Graduation, Geographic Designation, Employment Status, Position, Area of Responsibility and Place of Work. A link back to the Table of contents is in cell A2 and A100.
A2: Back to the Table of contents
A3: =IF(A6="All Physicians",CONCATENATE("Provincial/territorial profile for ",LOWER(A6)," ","in"," ",B6,", ",D6),IF(A6="Family medicine physicians",CONCATENATE("Provincial/territorial profile for ",LOWER(A6)," in"," ",B6,", ",D6),IF(A6="Specialists",CONCATENATE("Provincial/territorial profile for ","specialist"," physicians in"," ",B6,", ",D6),CONCATENATE("Provincial/territorial profile for ",LOWER(A6)," workforce in ",B6,", ",LOWER(C6),", ",D6)))) -> Provincial/territorial profile for registered nurses workforce in Ontario, all places of work, 2023
A4: Instructions: Select a provider, jurisdiction, place of work and year from the drop-down lists in cells A6, B6, C6 and D6.
A5: Type of provider | B5: Province/territory | C5: Place of work* | D5: Year
A6: Registered nurses | B6: Ontario | C6: All places of work | D6: 2023
A7: Data will change in the figures and table below based on your selections above. Hover over the chart area to show values and categories. When a figure does not populate, it indicates that data for the selection is unavailable, does not exist or is not applicable.
A8: The information can be found in the table below.
A9: =CONCATENATE("Table 1 "," ",A3) -> Table 1 Provincial/territorial profile for registered nurses workforce in Ontario, all places of work, 2023
A10: Data element | B10: Category | C10: Count | D10: Percentage
A11: Sex | B11: Female | C11: =IF(A6="Family medicine physicians",IFERROR(VLOOKUP(CONCATENATE($D$6,$A$6,$B$6),Phyprofile!A3:AU464,6,FALSE),"—"),IF(A6="Specialists",IFERROR(VLOOKUP(CONCATENATE($D$6,$A$6,$B$6),Phyprofile!A3:AU464,6,FALSE),"—"),IF(A6="All physicians",IFERROR(VLOOKUP(CONCATENATE($D$6,$A$6,$B$6),Phyprofile!A3:AU464,6,FALSE),"—"),IF(A6="Occupational therapists",IFERROR(VLOOKUP(CONCATENATE($D$6,$A$6,$B$6,$C$6),OTProfileData!$A$2:$AR$1920,6,FALSE),"—"),IF(A6="Physiotherapists",IFERROR(VLOOKUP(CONCATENATE($D$6,$A$6,$B$6,$C$6),PTProfileData!$A$2:$BV$1802,6,FALSE),"—"),IF(A6="Pharmacists",IFERROR(VLOOKUP(CONCATENATE($D$6,$A$6,$B$6,$C$6),PHProfileData!$A$3:$AO$1868,6,FALSE),"—"),IF(A6="nurse practitioners",IFERROR(VLOOKUP(CONCATENATE($D$6,$A$6,$B$6,$C$6),NursProfileData!$A$2:$AN$2066,6,FALSE),"—"),IF(A6="Registered nurses",IFERROR(VLOOKUP(CONCATENATE($D$6,$A$6,$B$6,$C$6),NursProfileData!$A$2:$AN$2066,6,FALSE),"—"),IF(A6="Registered psychiatric nurses",IFERROR(VLOOKUP(CONCATENATE($D$6,$A$6,$B$6,$C$6),NursProfileData!$A$2:$AN$2066,6,FALSE),"—"),IF(A6="Licensed practical nurses",IFERROR(VLOOKUP(CONCATENATE($D$6,$A$6,$B$6,$C$6),NursProfileData!$A$2:$AN$2066,6,FALSE),"—"),"-")))))))))) -> 92239 | D11: =IF(A6="Family medicine physicians",IFERROR(VLOOKUP(CONCATENATE($D$6,$A$6,$B$6),Phyprofile!$A$2:$AU$464,27,FALSE),"—"),IF(A6="Specialists",IFERROR(VLOOKUP(CONCATENATE($D$6,$A$6,$B$6),Phyprofile!$A$2:$AU$464,27,FALSE),"—"),IF(A6="All physicians",IFERROR(VLOOKUP(CONCATENATE($D$6,$A$6,$B$6),Phyprofile!$A$2:$AU$464,27,FALSE),"—"),IF(A6="Occupational therapists",IFERROR(VLOOKUP(CONCATENATE($D$6,$A$6,$B$6,$C$6),OTProfileData!$A$2:$CB$1920,42,FALSE),"—"),IF(A6="Physiotherapists",IFERROR(VLOOKUP(CONCATENATE($D$6,$A$6,$B$6,$C$6),PTProfileData!$A$2:$BW$1802,39,FALSE),"—"),IF(A6="Pharmacists",IFERROR(VLOOKUP(CONCATENATE($D$6,$A$6,$B$6,$C$6),PHProfileData!$A$3:$BR$1868,37,FALSE),"—"),IF(A6="nurse practitioners",IFERROR(VLOOKUP(CONCATENATE($D$6,$A$6,$B$6,$C$6),NursProfileData!$A$2:$BZ$2066,41,FALSE),"—"),IF(A6="Registered nurses",IFERROR(VLOOKUP(CONCATENATE($D$6,$A$6,$B$6,$C$6),NursProfileData!$A$2:$BZ$2066,41,FALSE),"—"),IF(A6="Registered psychiatric nurses",IFERROR(VLOOKUP(CONCATENATE($D$6,$A$6,$B$6,$C$6),NursProfileData!$A$2:$BZ$2066,41,FALSE),"—"),IF(A6="Licensed practical nurses",IFERROR(VLOOKUP(CONCATENATE($D$6,$A$6,$B$6,$C$6),NursProfileData!$A$2:$BZ$2066,41,FALSE),"—"),"-")))))))))) -> 0.90787311
B12: Male | C12: =IF(A6="Family medicine physicians",IFERROR(VLOOKUP(CONCATENATE($D$6,$A$6,$B$6),Phyprofile!A3:AU464,7,FALSE),"—"),IF(A6="Specialists",IFERROR(VLOOKUP(CONCATENATE($D$6,$A$6,$B$6),Phyprofile!A3:AU464,7,FALSE),"—"),IF(A6="All physicians",IFERROR(VLOOKUP(CONCATENATE($D$6,$A$6,$B$6),Phyprofile!A3:AU464,7,FALSE),"—"),IF(A6="Occupational therapists",IFERROR(VLOOKUP(CONCATENATE($D$6,$A$6,$B$6,$C$6),OTProfileData!$A$2:$AR$1920,7,FALSE),"—"),IF(A6="Physiotherapists",IFERROR(VLOOKUP(CONCATENATE($D$6,$A$6,$B$6,$C$6),PTProfileData!$A$2:$BW$1802,7,FALSE),"—"),IF(A6="Pharmacists",IFERROR(VLOOKUP(CONCATENATE($D$6,$A$6,$B$6,$C$6),PHProfileData!$A$3:$AO$1868,7,FALSE),"—"),IF(A6="nurse practitioners",IFERROR(VLOOKUP(CONCATENATE($D$6,$A$6,$B$6,$C$6),NursProfileData!$A$2:$AN$2066,7,FALSE),"—"),IF(A6="Registered nurses",IFERROR(VLOOKUP(CONCATENATE($D$6,$A$6,$B$6,$C$6),NursProfileData!$A$2:$AN$2066,7,FALSE),"—"),IF(A6="Registered psychiatric nurses",IFERROR(VLOOKUP(CONCATENATE($D$6,$A$6,$B$6,$C$6),NursProfileData!$A$2:$AN$2066,7,FALSE),"—"),IF(A6="Licensed practical nurses",IFERROR(VLOOKUP(CONCATENATE($D$6,$A$6,$B$6,$C$6),NursProfileData!$A$2:$AN$2066,7,FALSE),"—"),"-")))))))))) -> 9304 | D12: =IF(A6="Family medicine physicians",IFERROR(VLOOKUP(CONCATENATE($D$6,$A$6,$B$6),Phyprofile!A3:AU464,28,FALSE),"—"),IF(A6="Specialists",IFERROR(VLOOKUP(CONCATENATE($D$6,$A$6,$B$6),Phyprofile!A3:AU464,28,FALSE),"—"),IF(A6="All physicians",IFERROR(VLOOKUP(CONCATENATE($D$6,$A$6,$B$6),Phyprofile!A3:AU464,28,FALSE),"—"),IF(A6="Occupational therapists",IFERROR(VLOOKUP(CONCATENATE($D$6,$A$6,$B$6,$C$6),OTProfileData!$A$2:$CB$1920,43,FALSE),"—"),IF(A6="Physiotherapists",IFERROR(VLOOKUP(CONCATENATE($D$6,$A$6,$B$6,$C$6),PTProfileData!$A$2:$BW$1802,40,FALSE),"—"),IF(A6="Pharmacists",IFERROR(VLOOKUP(CONCATENATE($D$6,$A$6,$B$6,$C$6),PHProfileData!$A$3:$BR$1868,38,FALSE),"—"),IF(A6="nurse practitioners",IFERROR(VLOOKUP(CONCATENATE($D$6,$A$6,$B$6,$C$6),NursProfileData!$A$2:$BZ$2066,42,FALSE),"—"),IF(A6="Registered nurses",IFERROR(VLOOKUP(CONCATENATE($D$6,$A$6,$B$6,$C$6),NursProfileData!$A$2:$BZ$2066,42,FALSE),"—"),IF(A6="Registered psychiatric nurses",IFERROR(VLOOKUP(CONCATENATE($D$6,$A$6,$B$6,$C$6),NursProfileData!$A$2:$BZ$2066,42,FALSE),"—"),IF(A6="Licensed practical nurses",IFERROR(VLOOKUP(CONCATENATE($D$6,$A$6,$B$6,$C$6),NursProfileData!$A$2:$BZ$2066,42,FALSE),"—"),"-")))))))))) -> 0.091575704
B13: Not stated | C13: =IF(A6="Family medicine physicians",IFERROR(VLOOKUP(CONCATENATE($D$6,$A$6,$B$6),Phyprofile!A3:AU464,8,FALSE),"—"),IF(A6="Specialists",IFERROR(VLOOKUP(CONCATENATE($D$6,$A$6,$B$6),Phyprofile!A3:AU464,8,FALSE),"—"),IF(A6="All physicians",IFERROR(VLOOKUP(CONCATENATE($D$6,$A$6,$B$6),Phyprofile!A3:AU464,8,FALSE),"—"),IF(A6="Occupational therapists",IFERROR(VLOOKUP(CONCATENATE($D$6,$A$6,$B$6,$C$6),OTProfileData!$A$2:$AR$1920,8,FALSE),"—"),IF(A6="Physiotherapists",IFERROR(VLOOKUP(CONCATENATE($D$6,$A$6,$B$6,$C$6),PTProfileData!$A$2:$BW$1802,8,FALSE),"—"),IF(A6="Pharmacists",IFERROR(VLOOKUP(CONCATENATE($D$6,$A$6,$B$6,$C$6),PHProfileData!$A$3:$AO$1868,8,FALSE),"—"),IF(A6="nurse practitioners",IFERROR(VLOOKUP(CONCATENATE($D$6,$A$6,$B$6,$C$6),NursProfileData!$A$2:$AN$2066,8,FALSE),"—"),IF(A6="Registered nurses",IFERROR(VLOOKUP(CONCATENATE($D$6,$A$6,$B$6,$C$6),NursProfileData!$A$2:$AN$2066,8,FALSE),"—"),IF(A6="Registered psychiatric nurses",IFERROR(VLOOKUP(CONCATENATE($D$6,$A$6,$B$6,$C$6),NursProfileData!$A$2:$AN$2066,8,FALSE),"—"),IF(A6="Licensed practical nurses",IFERROR(VLOOKUP(CONCATENATE($D$6,$A$6,$B$6,$C$6),NursProfileData!$A$2:$AN$243,8,FALSE),"—"),"-")))))))))) -> 56 | D13: =IF(A6="Family medicine physicians",IFERROR(VLOOKUP(CONCATENATE($D$6,$A$6,$B$6),Phyprofile!A3:AU464,29,FALSE),"—"),IF(A6="Specialists",IFERROR(VLOOKUP(CONCATENATE($D$6,$A$6,$B$6),Phyprofile!A3:AU464,29,FALSE),"—"),IF(A6="All physicians",IFERROR(VLOOKUP(CONCATENATE($D$6,$A$6,$B$6),Phyprofile!A3:AU464,29,FALSE),"—"),IF(A6="Occupational therapists",IFERROR(VLOOKUP(CONCATENATE($D$6,$A$6,$B$6,$C$6),OTProfileData!$A$2:$CB$1920,44,FALSE),"—"),IF(A6="Physiotherapists",IFERROR(VLOOKUP(CONCATENATE($D$6,$A$6,$B$6,$C$6),PTProfileData!$A$2:$BW$1802,41,FALSE),"—"),IF(A6="Pharmacists",IFERROR(VLOOKUP(CONCATENATE($D$6,$A$6,$B$6,$C$6),PHProfileData!$A$3:$BR$1868,39,FALSE),"—"),IF(A6="nurse practitioners",IFERROR(VLOOKUP(CONCATENATE($D$6,$A$6,$B$6,$C$6),NursProfileData!$A$2:$BZ$2066,43,FALSE),"—"),IF(A6="Registered nurses",IFERROR(VLOOKUP(CONCATENATE($D$6,$A$6,$B$6,$C$6),NursProfileData!$A$2:$BZ$2066,43,FALSE),"—"),IF(A6="Registered psychiatric nurses",IFERROR(VLOOKUP(CONCATENATE($D$6,$A$6,$B$6,$C$6),NursProfileData!$A$2:$BZ$2066,43,FALSE),"—"),IF(A6="Licensed practical nurses",IFERROR(VLOOKUP(CONCATENATE($D$6,$A$6,$B$6,$C$6),NursProfileData!$A$2:$BZ$2066,43,FALSE),"—"),"-")))))))))) -> 0.00055118653
A14: Age Group | B14: <25 | C14: =IF(A6="Family medicine physicians",IFERROR(VLOOKUP(CONCATENATE($D$6,$A$6,$B$6),Phyprofile!A3:AU464,19,FALSE),"—"),IF(A6="Specialists",IFERROR(VLOOKUP(CONCATENATE($D$6,$A$6,$B$6),Phyprofile!A3:AU464,19,FALSE),"—"),IF(A6="All physicians",IFERROR(VLOOKUP(CONCATENATE($D$6,$A$6,$B$6),Phyprofile!A3:AU464,19,FALSE),"—"),IF(A6="Occupational therapists",IFERROR(VLOOKUP(CONCATENATE($D$6,$A$6,$B$6,$C$6),OTProfileData!$A$2:$AR$1920,19,FALSE),"—"),IF(A6="Physiotherapists",IFERROR(VLOOKUP(CONCATENATE($D$6,$A$6,$B$6,$C$6),PTProfileData!$A$2:$BW$1802,19,FALSE),"—"),IF(A6="Pharmacists",IFERROR(VLOOKUP(CONCATENATE($D$6,$A$6,$B$6,$C$6),PHProfileData!$A$3:$AO$1868,19,FALSE),"—"),IF(A6="nurse practitioners",IFERROR(VLOOKUP(CONCATENATE($D$6,$A$6,$B$6,$C$6),NursProfileData!$A$2:$BZ$2066,19,FALSE),"—"),IF(A6="Registered nurses",IFERROR(VLOOKUP(CONCATENATE($D$6,$A$6,$B$6,$C$6),NursProfileData!$A$2:$BZ$2066,19,FALSE),"—"),IF(A6="Registered psychiatric nurses",IFERROR(VLOOKUP(CONCATENATE($D$6,$A$6,$B$6,$C$6),NursProfileData!$A$2:$BZ$2066,19,FALSE),"—"),IF(A6="Licensed practical nurses",IFERROR(VLOOKUP(CONCATENATE($D$6,$A$6,$B$6,$C$6),NursProfileData!$A$2:$BZ$2066,19,FALSE),"—"),"-")))))))))) -> 2751 | D14: =IF(A6="Family medicine physicians",IFERROR(VLOOKUP(CONCATENATE($D$6,$A$6,$B$6),Phyprofile!A3:AU464,40,FALSE),"—"),IF(A6="Specialists",IFERROR(VLOOKUP(CONCATENATE($D$6,$A$6,$B$6),Phyprofile!A3:AU464,40,FALSE),"—"),IF(A6="All physicians",IFERROR(VLOOKUP(CONCATENATE($D$6,$A$6,$B$6),Phyprofile!A3:AU464,40,FALSE),"—"),IF(A6="Occupational therapists",IFERROR(VLOOKUP(CONCATENATE($D$6,$A$6,$B$6,$C$6),OTProfileData!$A$2:$CB$1920,55,FALSE),"—"),IF(A6="Physiotherapists",IFERROR(VLOOKUP(CONCATENATE($D$6,$A$6,$B$6,$C$6),PTProfileData!$A$2:$BW$1802,52,FALSE),"—"),IF(A6="Pharmacists",IFERROR(VLOOKUP(CONCATENATE($D$6,$A$6,$B$6,$C$6),PHProfileData!$A$3:$BR$1868,50,FALSE),"—"),IF(A6="nurse practitioners",IFERROR(VLOOKUP(CONCATENATE($D$6,$A$6,$B$6,$C$6),NursProfileData!$A$2:$BZ$2066,54,FALSE),"—"),IF(A6="Registered nurses",IFERROR(VLOOKUP(CONCATENATE($D$6,$A$6,$B$6,$C$6),NursProfileData!$A$2:$BZ$2066,54,FALSE),"—"),IF(A6="Registered psychiatric nurses",IFERROR(VLOOKUP(CONCATENATE($D$6,$A$6,$B$6,$C$6),NursProfileData!$A$2:$BZ$2066,54,FALSE),"—"),IF(A6="Licensed practical nurses",IFERROR(VLOOKUP(CONCATENATE($D$6,$A$6,$B$6,$C$6),NursProfileData!$A$2:$BZ$2066,54,FALSE),"—"),"-")))))))))) -> 0.017992303
B15: 25–29 | C15: =IF(A6="Family medicine physicians",IFERROR(VLOOKUP(CONCATENATE($D$6,$A$6,$B$6),Phyprofile!A3:AU464,9,FALSE),"—"),IF(A6="Specialists",IFERROR(VLOOKUP(CONCATENATE($D$6,$A$6,$B$6),Phyprofile!A3:AU464,9,FALSE),"—"),IF(A6="All physicians",IFERROR(VLOOKUP(CONCATENATE($D$6,$A$6,$B$6),Phyprofile!A3:AU464,9,FALSE),"—"),IF(A6="Occupational therapists",IFERROR(VLOOKUP(CONCATENATE($D$6,$A$6,$B$6,$C$6),OTProfileData!$A$2:$AR$1920,9,FALSE),"—"),IF(A6="Physiotherapists",IFERROR(VLOOKUP(CONCATENATE($D$6,$A$6,$B$6,$C$6),PTProfileData!$A$2:$BW$1802,9,FALSE),"—"),IF(A6="Pharmacists",IFERROR(VLOOKUP(CONCATENATE($D$6,$A$6,$B$6,$C$6),PHProfileData!$A$3:$AO$1868,9,FALSE),"—"),IF(A6="nurse practitioners",IFERROR(VLOOKUP(CONCATENATE($D$6,$A$6,$B$6,$C$6),NursProfileData!$A$2:$BZ$2066,9,FALSE),"—"),IF(A6="Registered nurses",IFERROR(VLOOKUP(CONCATENATE($D$6,$A$6,$B$6,$C$6),NursProfileData!$A$2:$BZ$2066,9,FALSE),"—"),IF(A6="Registered psychiatric nurses",IFERROR(VLOOKUP(CONCATENATE($D$6,$A$6,$B$6,$C$6),NursProfileData!$A$2:$BZ$2066,9,FALSE),"—"),IF(A6="Licensed practical nurses",IFERROR(VLOOKUP(CONCATENATE($D$6,$A$6,$B$6,$C$6),NursProfileData!$A$2:$BZ$2066,9,FALSE),"—"),"-")))))))))) -> 12945 | D15: =IF(A6="Family medicine physicians",IFERROR(VLOOKUP(CONCATENATE($D$6,$A$6,$B$6),Phyprofile!A3:AU464,30,FALSE),"—"),IF(A6="Specialists",IFERROR(VLOOKUP(CONCATENATE($D$6,$A$6,$B$6),Phyprofile!A3:AU464,30,FALSE),"—"),IF(A6="All physicians",IFERROR(VLOOKUP(CONCATENATE($D$6,$A$6,$B$6),Phyprofile!A3:AU464,30,FALSE),"—"),IF(A6="Occupational therapists",IFERROR(VLOOKUP(CONCATENATE($D$6,$A$6,$B$6,$C$6),OTProfileData!$A$2:$CB$1920,45,FALSE),"—"),IF(A6="Physiotherapists",IFERROR(VLOOKUP(CONCATENATE($D$6,$A$6,$B$6,$C$6),PTProfileData!$A$2:$BW$1802,42,FALSE),"—"),IF(A6="Pharmacists",IFERROR(VLOOKUP(CONCATENATE($D$6,$A$6,$B$6,$C$6),PHProfileData!$A$3:$BR$1868,40,FALSE),"—"),IF(A6="nurse practitioners",IFERROR(VLOOKUP(CONCATENATE($D$6,$A$6,$B$6,$C$6),NursProfileData!$A$2:$BZ$2066,44,FALSE),"—"),IF(A6="Registered nurses",IFERROR(VLOOKUP(CONCATENATE($D$6,$A$6,$B$6,$C$6),NursProfileData!$A$2:$BZ$2066,44,FALSE),"—"),IF(A6="Registered psychiatric nurses",IFERROR(VLOOKUP(CONCATENATE($D$6,$A$6,$B$6,$C$6),NursProfileData!$A$2:$BZ$2066,44,FALSE),"—"),IF(A6="Licensed practical nurses",IFERROR(VLOOKUP(CONCATENATE($D$6,$A$6,$B$6,$C$6),NursProfileData!$A$2:$BZ$2066,44,FALSE),"—"),"-")))))))))) -> 0.12741267
B16: 30–34 | C16: =IF(A6="Family medicine physicians",IFERROR(VLOOKUP(CONCATENATE($D$6,$A$6,$B$6),Phyprofile!A3:AU464,10,FALSE),"—"),IF(A6="Specialists",IFERROR(VLOOKUP(CONCATENATE($D$6,$A$6,$B$6),Phyprofile!A3:AU464,10,FALSE),"—"),IF(A6="All physicians",IFERROR(VLOOKUP(CONCATENATE($D$6,$A$6,$B$6),Phyprofile!A3:AU464,10,FALSE),"—"),IF(A6="Occupational therapists",IFERROR(VLOOKUP(CONCATENATE($D$6,$A$6,$B$6,$C$6),OTProfileData!$A$2:$AR$1920,10,FALSE),"—"),IF(A6="Physiotherapists",IFERROR(VLOOKUP(CONCATENATE($D$6,$A$6,$B$6,$C$6),PTProfileData!$A$2:$BW$1802,10,FALSE),"—"),IF(A6="Pharmacists",IFERROR(VLOOKUP(CONCATENATE($D$6,$A$6,$B$6,$C$6),PHProfileData!$A$3:$AO$1868,10,FALSE),"—"),IF(A6="nurse practitioners",IFERROR(VLOOKUP(CONCATENATE($D$6,$A$6,$B$6,$C$6),NursProfileData!$A$2:$BZ$2066,10,FALSE),"—"),IF(A6="Registered nurses",IFERROR(VLOOKUP(CONCATENATE($D$6,$A$6,$B$6,$C$6),NursProfileData!$A$2:$BZ$2066,10,FALSE),"—"),IF(A6="Registered psychiatric nurses",IFERROR(VLOOKUP(CONCATENATE($D$6,$A$6,$B$6,$C$6),NursProfileData!$A$2:$BZ$2066,10,FALSE),"—"),IF(A6="Licensed practical nurses",IFERROR(VLOOKUP(CONCATENATE($D$6,$A$6,$B$6,$C$6),NursProfileData!$A$2:$BZ$2066,10,FALSE),"—"),"-")))))))))) -> 15108 | D16: =IF(A6="Family medicine physicians",IFERROR(VLOOKUP(CONCATENATE($D$6,$A$6,$B$6),Phyprofile!A3:AU464,31,FALSE),"—"),IF(A6="Specialists",IFERROR(VLOOKUP(CONCATENATE($D$6,$A$6,$B$6),Phyprofile!A3:AU464,31,FALSE),"—"),IF(A6="All physicians",IFERROR(VLOOKUP(CONCATENATE($D$6,$A$6,$B$6),Phyprofile!A3:AU464,31,FALSE),"—"),IF(A6="Occupational therapists",IFERROR(VLOOKUP(CONCATENATE($D$6,$A$6,$B$6,$C$6),OTProfileData!$A$2:$CB$1920,46,FALSE),"—"),IF(A6="Physiotherapists",IFERROR(VLOOKUP(CONCATENATE($D$6,$A$6,$B$6,$C$6),PTProfileData!$A$2:$BW$1802,43,FALSE),"—"),IF(A6="Pharmacists",IFERROR(VLOOKUP(CONCATENATE($D$6,$A$6,$B$6,$C$6),PHProfileData!$A$3:$BR$1868,41,FALSE),"—"),IF(A6="nurse practitioners",IFERROR(VLOOKUP(CONCATENATE($D$6,$A$6,$B$6,$C$6),NursProfileData!$A$2:$BZ$2066,45,FALSE),"—"),IF(A6="Registered nurses",IFERROR(VLOOKUP(CONCATENATE($D$6,$A$6,$B$6,$C$6),NursProfileData!$A$2:$BZ$2066,45,FALSE),"—"),IF(A6="Registered psychiatric nurses",IFERROR(VLOOKUP(CONCATENATE($D$6,$A$6,$B$6,$C$6),NursProfileData!$A$2:$BZ$2066,45,FALSE),"—"),IF(A6="Licensed practical nurses",IFERROR(VLOOKUP(CONCATENATE($D$6,$A$6,$B$6,$C$6),NursProfileData!$A$2:$BZ$2066,45,FALSE),"—"),"-")))))))))) -> 0.14870225
B17: 35–39 | C17: =IF(A6="Family medicine physicians",IFERROR(VLOOKUP(CONCATENATE($D$6,$A$6,$B$6),Phyprofile!A3:AU464,11,FALSE),"—"),IF(A6="Specialists",IFERROR(VLOOKUP(CONCATENATE($D$6,$A$6,$B$6),Phyprofile!A3:AU464,11,FALSE),"—"),IF(A6="All physicians",IFERROR(VLOOKUP(CONCATENATE($D$6,$A$6,$B$6),Phyprofile!A3:AU464,11,FALSE),"—"),IF(A6="Occupational therapists",IFERROR(VLOOKUP(CONCATENATE($D$6,$A$6,$B$6,$C$6),OTProfileData!$A$2:$AR$1920,11,FALSE),"—"),IF(A6="Physiotherapists",IFERROR(VLOOKUP(CONCATENATE($D$6,$A$6,$B$6,$C$6),PTProfileData!$A$2:$BW$1802,11,FALSE),"—"),IF(A6="Pharmacists",IFERROR(VLOOKUP(CONCATENATE($D$6,$A$6,$B$6,$C$6),PHProfileData!$A$3:$AO$1868,11,FALSE),"—"),IF(A6="nurse practitioners",IFERROR(VLOOKUP(CONCATENATE($D$6,$A$6,$B$6,$C$6),NursProfileData!$A$2:$BZ$2066,11,FALSE),"—"),IF(A6="Registered nurses",IFERROR(VLOOKUP(CONCATENATE($D$6,$A$6,$B$6,$C$6),NursProfileData!$A$2:$BZ$2066,11,FALSE),"—"),IF(A6="Registered psychiatric nurses",IFERROR(VLOOKUP(CONCATENATE($D$6,$A$6,$B$6,$C$6),NursProfileData!$A$2:$BZ$2066,11,FALSE),"—"),IF(A6="Licensed practical nurses",IFERROR(VLOOKUP(CONCATENATE($D$6,$A$6,$B$6,$C$6),NursProfileData!$A$2:$BZ$2066,11,FALSE),"—"),"-")))))))))) -> 14168 | D17: =IF(A6="Family medicine physicians",IFERROR(VLOOKUP(CONCATENATE($D$6,$A$6,$B$6),Phyprofile!A3:AU464,32,FALSE),"—"),IF(A6="Specialists",IFERROR(VLOOKUP(CONCATENATE($D$6,$A$6,$B$6),Phyprofile!A3:AU464,32,FALSE),"—"),IF(A6="All physicians",IFERROR(VLOOKUP(CONCATENATE($D$6,$A$6,$B$6),Phyprofile!A3:AU464,32,FALSE),"—"),IF(A6="Occupational therapists",IFERROR(VLOOKUP(CONCATENATE($D$6,$A$6,$B$6,$C$6),OTProfileData!$A$2:$CB$1920,47,FALSE),"—"),IF(A6="Physiotherapists",IFERROR(VLOOKUP(CONCATENATE($D$6,$A$6,$B$6,$C$6),PTProfileData!$A$2:$BW$1802,44,FALSE),"—"),IF(A6="Pharmacists",IFERROR(VLOOKUP(CONCATENATE($D$6,$A$6,$B$6,$C$6),PHProfileData!$A$3:$BR$1868,42,FALSE),"—"),IF(A6="nurse practitioners",IFERROR(VLOOKUP(CONCATENATE($D$6,$A$6,$B$6,$C$6),NursProfileData!$A$2:$BZ$2066,46,FALSE),"—"),IF(A6="Registered nurses",IFERROR(VLOOKUP(CONCATENATE($D$6,$A$6,$B$6,$C$6),NursProfileData!$A$2:$BZ$2066,46,FALSE),"—"),IF(A6="Registered psychiatric nurses",IFERROR(VLOOKUP(CONCATENATE($D$6,$A$6,$B$6,$C$6),NursProfileData!$A$2:$BZ$2066,46,FALSE),"—"),IF(A6="Licensed practical nurses",IFERROR(VLOOKUP(CONCATENATE($D$6,$A$6,$B$6,$C$6),NursProfileData!$A$2:$BZ$2066,46,FALSE),"—"),"-")))))))))) -> 0.13945019
B18: 40–44 | C18: =IF(A6="Family medicine physicians",IFERROR(VLOOKUP(CONCATENATE($D$6,$A$6,$B$6),Phyprofile!A3:AU464,12,FALSE),"—"),IF(A6="Specialists",IFERROR(VLOOKUP(CONCATENATE($D$6,$A$6,$B$6),Phyprofile!A3:AU464,12,FALSE),"—"),IF(A6="All physicians",IFERROR(VLOOKUP(CONCATENATE($D$6,$A$6,$B$6),Phyprofile!A3:AU464,12,FALSE),"—"),IF(A6="Occupational therapists",IFERROR(VLOOKUP(CONCATENATE($D$6,$A$6,$B$6,$C$6),OTProfileData!$A$2:$AR$1920,12,FALSE),"—"),IF(A6="Physiotherapists",IFERROR(VLOOKUP(CONCATENATE($D$6,$A$6,$B$6,$C$6),PTProfileData!$A$2:$BW$1802,12,FALSE),"—"),IF(A6="Pharmacists",IFERROR(VLOOKUP(CONCATENATE($D$6,$A$6,$B$6,$C$6),PHProfileData!$A$3:$AO$1868,12,FALSE),"—"),IF(A6="nurse practitioners",IFERROR(VLOOKUP(CONCATENATE($D$6,$A$6,$B$6,$C$6),NursProfileData!$A$2:$BZ$2066,12,FALSE),"—"),IF(A6="Registered nurses",IFERROR(VLOOKUP(CONCATENATE($D$6,$A$6,$B$6,$C$6),NursProfileData!$A$2:$BZ$2066,12,FALSE),"—"),IF(A6="Registered psychiatric nurses",IFERROR(VLOOKUP(CONCATENATE($D$6,$A$6,$B$6,$C$6),NursProfileData!$A$2:$BZ$2066,12,FALSE),"—"),IF(A6="Licensed practical nurses",IFERROR(VLOOKUP(CONCATENATE($D$6,$A$6,$B$6,$C$6),NursProfileData!$A$2:$BZ$2066,12,FALSE),"—"),"-")))))))))) -> 11053 | D18: =IF(A6="Family medicine physicians",IFERROR(VLOOKUP(CONCATENATE($D$6,$A$6,$B$6),Phyprofile!A3:AU464,33,FALSE),"—"),IF(A6="Specialists",IFERROR(VLOOKUP(CONCATENATE($D$6,$A$6,$B$6),Phyprofile!A3:AU464,33,FALSE),"—"),IF(A6="All physicians",IFERROR(VLOOKUP(CONCATENATE($D$6,$A$6,$B$6),Phyprofile!A3:AU464,33,FALSE),"—"),IF(A6="Occupational therapists",IFERROR(VLOOKUP(CONCATENATE($D$6,$A$6,$B$6,$C$6),OTProfileData!$A$2:$CB$1920,48,FALSE),"—"),IF(A6="Physiotherapists",IFERROR(VLOOKUP(CONCATENATE($D$6,$A$6,$B$6,$C$6),PTProfileData!$A$2:$BW$1802,45,FALSE),"—"),IF(A6="Pharmacists",IFERROR(VLOOKUP(CONCATENATE($D$6,$A$6,$B$6,$C$6),PHProfileData!$A$3:$BR$1868,43,FALSE),"—"),IF(A6="nurse practitioners",IFERROR(VLOOKUP(CONCATENATE($D$6,$A$6,$B$6,$C$6),NursProfileData!$A$2:$BZ$2066,47,FALSE),"—"),IF(A6="Registered nurses",IFERROR(VLOOKUP(CONCATENATE($D$6,$A$6,$B$6,$C$6),NursProfileData!$A$2:$BZ$2066,47,FALSE),"—"),IF(A6="Registered psychiatric nurses",IFERROR(VLOOKUP(CONCATENATE($D$6,$A$6,$B$6,$C$6),NursProfileData!$A$2:$BZ$2066,47,FALSE),"—"),IF(A6="Licensed practical nurses",IFERROR(VLOOKUP(CONCATENATE($D$6,$A$6,$B$6,$C$6),NursProfileData!$A$2:$BZ$2066,47,FALSE),"—"),"-")))))))))) -> 0.10879044
B19: 45–49 | C19: =IF(A6="Family medicine physicians",IFERROR(VLOOKUP(CONCATENATE($D$6,$A$6,$B$6),Phyprofile!A3:AU464,13,FALSE),"—"),IF(A6="Specialists",IFERROR(VLOOKUP(CONCATENATE($D$6,$A$6,$B$6),Phyprofile!A3:AU464,13,FALSE),"—"),IF(A6="All physicians",IFERROR(VLOOKUP(CONCATENATE($D$6,$A$6,$B$6),Phyprofile!A3:AU464,13,FALSE),"—"),IF(A6="Occupational therapists",IFERROR(VLOOKUP(CONCATENATE($D$6,$A$6,$B$6,$C$6),OTProfileData!$A$2:$AR$1920,13,FALSE),"—"),IF(A6="Physiotherapists",IFERROR(VLOOKUP(CONCATENATE($D$6,$A$6,$B$6,$C$6),PTProfileData!$A$2:$BW$1802,13,FALSE),"—"),IF(A6="Pharmacists",IFERROR(VLOOKUP(CONCATENATE($D$6,$A$6,$B$6,$C$6),PHProfileData!$A$3:$AO$1868,13,FALSE),"—"),IF(A6="nurse practitioners",IFERROR(VLOOKUP(CONCATENATE($D$6,$A$6,$B$6,$C$6),NursProfileData!$A$2:$BZ$2066,13,FALSE),"—"),IF(A6="Registered nurses",IFERROR(VLOOKUP(CONCATENATE($D$6,$A$6,$B$6,$C$6),NursProfileData!$A$2:$BZ$2066,13,FALSE),"—"),IF(A6="Registered psychiatric nurses",IFERROR(VLOOKUP(CONCATENATE($D$6,$A$6,$B$6,$C$6),NursProfileData!$A$2:$BZ$2066,13,FALSE),"—"),IF(A6="Licensed practical nurses",IFERROR(VLOOKUP(CONCATENATE($D$6,$A$6,$B$6,$C$6),NursProfileData!$A$2:$BZ$2066,13,FALSE),"—"),"-")))))))))) -> 10105 | D19: =IF(A6="Family medicine physicians",IFERROR(VLOOKUP(CONCATENATE($D$6,$A$6,$B$6),Phyprofile!A3:AU464,34,FALSE),"—"),IF(A6="Specialists",IFERROR(VLOOKUP(CONCATENATE($D$6,$A$6,$B$6),Phyprofile!A3:AU464,34,FALSE),"—"),IF(A6="All physicians",IFERROR(VLOOKUP(CONCATENATE($D$6,$A$6,$B$6),Phyprofile!A3:AU464,34,FALSE),"—"),IF(A6="Occupational therapists",IFERROR(VLOOKUP(CONCATENATE($D$6,$A$6,$B$6,$C$6),OTProfileData!$A$2:$CB$1920,49,FALSE),"—"),IF(A6="Physiotherapists",IFERROR(VLOOKUP(CONCATENATE($D$6,$A$6,$B$6,$C$6),PTProfileData!$A$2:$BW$1802,46,FALSE),"—"),IF(A6="Pharmacists",IFERROR(VLOOKUP(CONCATENATE($D$6,$A$6,$B$6,$C$6),PHProfileData!$A$3:$BR$1868,44,FALSE),"—"),IF(A6="nurse practitioners",IFERROR(VLOOKUP(CONCATENATE($D$6,$A$6,$B$6,$C$6),NursProfileData!$A$2:$BZ$2066,48,FALSE),"—"),IF(A6="Registered nurses",IFERROR(VLOOKUP(CONCATENATE($D$6,$A$6,$B$6,$C$6),NursProfileData!$A$2:$BZ$2066,48,FALSE),"—"),IF(A6="Registered psychiatric nurses",IFERROR(VLOOKUP(CONCATENATE($D$6,$A$6,$B$6,$C$6),NursProfileData!$A$2:$BZ$2066,48,FALSE),"—"),IF(A6="Licensed practical nurses",IFERROR(VLOOKUP(CONCATENATE($D$6,$A$6,$B$6,$C$6),NursProfileData!$A$2:$BZ$2066,48,FALSE),"—"),"-")))))))))) -> 0.09945964
B20: 50–54 | C20: =IF(A6="Family medicine physicians",IFERROR(VLOOKUP(CONCATENATE($D$6,$A$6,$B$6),Phyprofile!A3:AU464,14,FALSE),"—"),IF(A6="Specialists",IFERROR(VLOOKUP(CONCATENATE($D$6,$A$6,$B$6),Phyprofile!A3:AU464,14,FALSE),"—"),IF(A6="All physicians",IFERROR(VLOOKUP(CONCATENATE($D$6,$A$6,$B$6),Phyprofile!A3:AU464,14,FALSE),"—"),IF(A6="Occupational therapists",IFERROR(VLOOKUP(CONCATENATE($D$6,$A$6,$B$6,$C$6),OTProfileData!$A$2:$AR$1920,14,FALSE),"—"),IF(A6="Physiotherapists",IFERROR(VLOOKUP(CONCATENATE($D$6,$A$6,$B$6,$C$6),PTProfileData!$A$2:$BW$1802,14,FALSE),"—"),IF(A6="Pharmacists",IFERROR(VLOOKUP(CONCATENATE($D$6,$A$6,$B$6,$C$6),PHProfileData!$A$3:$AO$1868,14,FALSE),"—"),IF(A6="nurse practitioners",IFERROR(VLOOKUP(CONCATENATE($D$6,$A$6,$B$6,$C$6),NursProfileData!$A$2:$BZ$2066,14,FALSE),"—"),IF(A6="Registered nurses",IFERROR(VLOOKUP(CONCATENATE($D$6,$A$6,$B$6,$C$6),NursProfileData!$A$2:$BZ$2066,14,FALSE),"—"),IF(A6="Registered psychiatric nurses",IFERROR(VLOOKUP(CONCATENATE($D$6,$A$6,$B$6,$C$6),NursProfileData!$A$2:$BZ$2066,14,FALSE),"—"),IF(A6="Licensed practical nurses",IFERROR(VLOOKUP(CONCATENATE($D$6,$A$6,$B$6,$C$6),NursProfileData!$A$2:$BZ$2066,14,FALSE),"—"),"-")))))))))) -> 11340 | D20: =IF(A6="Family medicine physicians",IFERROR(VLOOKUP(CONCATENATE($D$6,$A$6,$B$6),Phyprofile!A3:AU464,35,FALSE),"—"),IF(A6="Specialists",IFERROR(VLOOKUP(CONCATENATE($D$6,$A$6,$B$6),Phyprofile!A3:AU464,35,FALSE),"—"),IF(A6="All physicians",IFERROR(VLOOKUP(CONCATENATE($D$6,$A$6,$B$6),Phyprofile!A3:AU464,35,FALSE),"—"),IF(A6="Occupational therapists",IFERROR(VLOOKUP(CONCATENATE($D$6,$A$6,$B$6,$C$6),OTProfileData!$A$2:$CB$1920,50,FALSE),"—"),IF(A6="Physiotherapists",IFERROR(VLOOKUP(CONCATENATE($D$6,$A$6,$B$6,$C$6),PTProfileData!$A$2:$BW$1802,47,FALSE),"—"),IF(A6="Pharmacists",IFERROR(VLOOKUP(CONCATENATE($D$6,$A$6,$B$6,$C$6),PHProfileData!$A$3:$BR$1868,45,FALSE),"—"),IF(A6="nurse practitioners",IFERROR(VLOOKUP(CONCATENATE($D$6,$A$6,$B$6,$C$6),NursProfileData!$A$2:$BZ$2066,49,FALSE),"—"),IF(A6="Registered nurses",IFERROR(VLOOKUP(CONCATENATE($D$6,$A$6,$B$6,$C$6),NursProfileData!$A$2:$BZ$2066,49,FALSE),"—"),IF(A6="Registered psychiatric nurses",IFERROR(VLOOKUP(CONCATENATE($D$6,$A$6,$B$6,$C$6),NursProfileData!$A$2:$BZ$2066,49,FALSE),"—"),IF(A6="Licensed practical nurses",IFERROR(VLOOKUP(CONCATENATE($D$6,$A$6,$B$6,$C$6),NursProfileData!$A$2:$BZ$2066,49,FALSE),"—"),"-")))))))))) -> 0.11161527
B21: 55–59 | C21: =IF(A6="Family medicine physicians",IFERROR(VLOOKUP(CONCATENATE($D$6,$A$6,$B$6),Phyprofile!A3:AU464,15,FALSE),"—"),IF(A6="Specialists",IFERROR(VLOOKUP(CONCATENATE($D$6,$A$6,$B$6),Phyprofile!A3:AU464,15,FALSE),"—"),IF(A6="All physicians",IFERROR(VLOOKUP(CONCATENATE($D$6,$A$6,$B$6),Phyprofile!A3:AU464,15,FALSE),"—"),IF(A6="Occupational therapists",IFERROR(VLOOKUP(CONCATENATE($D$6,$A$6,$B$6,$C$6),OTProfileData!$A$2:$AR$1920,15,FALSE),"—"),IF(A6="Physiotherapists",IFERROR(VLOOKUP(CONCATENATE($D$6,$A$6,$B$6,$C$6),PTProfileData!$A$2:$BW$1802,15,FALSE),"—"),IF(A6="Pharmacists",IFERROR(VLOOKUP(CONCATENATE($D$6,$A$6,$B$6,$C$6),PHProfileData!$A$3:$AO$1868,15,FALSE),"—"),IF(A6="nurse practitioners",IFERROR(VLOOKUP(CONCATENATE($D$6,$A$6,$B$6,$C$6),NursProfileData!$A$2:$BZ$2066,15,FALSE),"—"),IF(A6="Registered nurses",IFERROR(VLOOKUP(CONCATENATE($D$6,$A$6,$B$6,$C$6),NursProfileData!$A$2:$BZ$2066,15,FALSE),"—"),IF(A6="Registered psychiatric nurses",IFERROR(VLOOKUP(CONCATENATE($D$6,$A$6,$B$6,$C$6),NursProfileData!$A$2:$BZ$2066,15,FALSE),"—"),IF(A6="Licensed practical nurses",IFERROR(VLOOKUP(CONCATENATE($D$6,$A$6,$B$6,$C$6),NursProfileData!$A$2:$BZ$2066,15,FALSE),"—"),"-")))))))))) -> 10730 | D21: =IF(A6="Family medicine physicians",IFERROR(VLOOKUP(CONCATENATE($D$6,$A$6,$B$6),Phyprofile!A3:AU464,36,FALSE),"—"),IF(A6="Specialists",IFERROR(VLOOKUP(CONCATENATE($D$6,$A$6,$B$6),Phyprofile!A3:AU464,36,FALSE),"—"),IF(A6="All physicians",IFERROR(VLOOKUP(CONCATENATE($D$6,$A$6,$B$6),Phyprofile!A3:AU464,36,FALSE),"—"),IF(A6="Occupational therapists",IFERROR(VLOOKUP(CONCATENATE($D$6,$A$6,$B$6,$C$6),OTProfileData!$A$2:$CB$1920,51,FALSE),"—"),IF(A6="Physiotherapists",IFERROR(VLOOKUP(CONCATENATE($D$6,$A$6,$B$6,$C$6),PTProfileData!$A$2:$BW$1802,48,FALSE),"—"),IF(A6="Pharmacists",IFERROR(VLOOKUP(CONCATENATE($D$6,$A$6,$B$6,$C$6),PHProfileData!$A$3:$BR$1868,46,FALSE),"—"),IF(A6="nurse practitioners",IFERROR(VLOOKUP(CONCATENATE($D$6,$A$6,$B$6,$C$6),NursProfileData!$A$2:$BZ$2066,50,FALSE),"—"),IF(A6="Registered nurses",IFERROR(VLOOKUP(CONCATENATE($D$6,$A$6,$B$6,$C$6),NursProfileData!$A$2:$BZ$2066,50,FALSE),"—"),IF(A6="Registered psychiatric nurses",IFERROR(VLOOKUP(CONCATENATE($D$6,$A$6,$B$6,$C$6),NursProfileData!$A$2:$BZ$2066,50,FALSE),"—"),IF(A6="Licensed practical nurses",IFERROR(VLOOKUP(CONCATENATE($D$6,$A$6,$B$6,$C$6),NursProfileData!$A$2:$BZ$2066,50,FALSE),"—"),"-")))))))))) -> 0.10561128
B22: 60–64 | C22: =IF(A6="Family medicine physicians",IFERROR(VLOOKUP(CONCATENATE($D$6,$A$6,$B$6),Phyprofile!A3:AU464,16,FALSE),"—"),IF(A6="Specialists",IFERROR(VLOOKUP(CONCATENATE($D$6,$A$6,$B$6),Phyprofile!A3:AU464,16,FALSE),"—"),IF(A6="All physicians",IFERROR(VLOOKUP(CONCATENATE($D$6,$A$6,$B$6),Phyprofile!A3:AU464,16,FALSE),"—"),IF(A6="Occupational therapists",IFERROR(VLOOKUP(CONCATENATE($D$6,$A$6,$B$6,$C$6),OTProfileData!$A$2:$AR$1920,16,FALSE),"—"),IF(A6="Physiotherapists",IFERROR(VLOOKUP(CONCATENATE($D$6,$A$6,$B$6,$C$6),PTProfileData!$A$2:$BW$1802,16,FALSE),"—"),IF(A6="Pharmacists",IFERROR(VLOOKUP(CONCATENATE($D$6,$A$6,$B$6,$C$6),PHProfileData!$A$3:$AO$1868,16,FALSE),"—"),IF(A6="nurse practitioners",IFERROR(VLOOKUP(CONCATENATE($D$6,$A$6,$B$6,$C$6),NursProfileData!$A$2:$BZ$2066,16,FALSE),"—"),IF(A6="Registered nurses",IFERROR(VLOOKUP(CONCATENATE($D$6,$A$6,$B$6,$C$6),NursProfileData!$A$2:$BZ$2066,16,FALSE),"—"),IF(A6="Registered psychiatric nurses",IFERROR(VLOOKUP(CONCATENATE($D$6,$A$6,$B$6,$C$6),NursProfileData!$A$2:$BZ$2066,16,FALSE),"—"),IF(A6="Licensed practical nurses",IFERROR(VLOOKUP(CONCATENATE($D$6,$A$6,$B$6,$C$6),NursProfileData!$A$2:$BZ$2066,16,FALSE),"—"),"-")))))))))) -> 7872 | D22: =IF(A6="Family medicine physicians",IFERROR(VLOOKUP(CONCATENATE($D$6,$A$6,$B$6),Phyprofile!A3:AU464,37,FALSE),"—"),IF(A6="Specialists",IFERROR(VLOOKUP(CONCATENATE($D$6,$A$6,$B$6),Phyprofile!A3:AU464,37,FALSE),"—"),IF(A6="All physicians",IFERROR(VLOOKUP(CONCATENATE($D$6,$A$6,$B$6),Phyprofile!A3:AU464,37,FALSE),"—"),IF(A6="Occupational therapists",IFERROR(VLOOKUP(CONCATENATE($D$6,$A$6,$B$6,$C$6),OTProfileData!$A$2:$CB$1920,52,FALSE),"—"),IF(A6="Physiotherapists",IFERROR(VLOOKUP(CONCATENATE($D$6,$A$6,$B$6,$C$6),PTProfileData!$A$2:$BW$1802,49,FALSE),"—"),IF(A6="Pharmacists",IFERROR(VLOOKUP(CONCATENATE($D$6,$A$6,$B$6,$C$6),PHProfileData!$A$3:$BR$1868,47,FALSE),"—"),IF(A6="nurse practitioners",IFERROR(VLOOKUP(CONCATENATE($D$6,$A$6,$B$6,$C$6),NursProfileData!$A$2:$BZ$2066,51,FALSE),"—"),IF(A6="Registered nurses",IFERROR(VLOOKUP(CONCATENATE($D$6,$A$6,$B$6,$C$6),NursProfileData!$A$2:$BZ$2066,51,FALSE),"—"),IF(A6="Registered psychiatric nurses",IFERROR(VLOOKUP(CONCATENATE($D$6,$A$6,$B$6,$C$6),NursProfileData!$A$2:$BZ$2066,51,FALSE),"—"),IF(A6="Licensed practical nurses",IFERROR(VLOOKUP(CONCATENATE($D$6,$A$6,$B$6,$C$6),NursProfileData!$A$2:$BZ$2066,51,FALSE),"—"),"-")))))))))) -> 0.077481078
B23: 65–69 | C23: =IF(A6="Family medicine physicians",IFERROR(VLOOKUP(CONCATENATE($D$6,$A$6,$B$6),Phyprofile!A3:AU464,17,FALSE),"—"),IF(A6="Specialists",IFERROR(VLOOKUP(CONCATENATE($D$6,$A$6,$B$6),Phyprofile!A3:AU464,17,FALSE),"—"),IF(A6="All physicians",IFERROR(VLOOKUP(CONCATENATE($D$6,$A$6,$B$6),Phyprofile!A3:AU464,17,FALSE),"—"),IF(A6="Occupational therapists",IFERROR(VLOOKUP(CONCATENATE($D$6,$A$6,$B$6,$C$6),OTProfileData!$A$2:$AR$1920,17,FALSE),"—"),IF(A6="Physiotherapists",IFERROR(VLOOKUP(CONCATENATE($D$6,$A$6,$B$6,$C$6),PTProfileData!$A$2:$BW$1802,17,FALSE),"—"),IF(A6="Pharmacists",IFERROR(VLOOKUP(CONCATENATE($D$6,$A$6,$B$6,$C$6),PHProfileData!$A$3:$AO$1868,17,FALSE),"—"),IF(A6="nurse practitioners",IFERROR(VLOOKUP(CONCATENATE($D$6,$A$6,$B$6,$C$6),NursProfileData!$A$2:$BZ$2066,17,FALSE),"—"),IF(A6="Registered nurses",IFERROR(VLOOKUP(CONCATENATE($D$6,$A$6,$B$6,$C$6),NursProfileData!$A$2:$BZ$2066,17,FALSE),"—"),IF(A6="Registered psychiatric nurses",IFERROR(VLOOKUP(CONCATENATE($D$6,$A$6,$B$6,$C$6),NursProfileData!$A$2:$BZ$2066,17,FALSE),"—"),IF(A6="Licensed practical nurses",IFERROR(VLOOKUP(CONCATENATE($D$6,$A$6,$B$6,$C$6),NursProfileData!$A$2:$BZ$2066,17,FALSE),"—"),"-")))))))))) -> 3699 | D23: =IF(A6="Family medicine physicians",IFERROR(VLOOKUP(CONCATENATE($D$6,$A$6,$B$6),Phyprofile!A3:AU464,38,FALSE),"—"),IF(A6="Specialists",IFERROR(VLOOKUP(CONCATENATE($D$6,$A$6,$B$6),Phyprofile!A3:AU464,38,FALSE),"—"),IF(A6="All physicians",IFERROR(VLOOKUP(CONCATENATE($D$6,$A$6,$B$6),Phyprofile!A3:AU464,38,FALSE),"—"),IF(A6="Occupational therapists",IFERROR(VLOOKUP(CONCATENATE($D$6,$A$6,$B$6,$C$6),OTProfileData!$A$2:$CB$1920,53,FALSE),"—"),IF(A6="Physiotherapists",IFERROR(VLOOKUP(CONCATENATE($D$6,$A$6,$B$6,$C$6),PTProfileData!$A$2:$BW$1802,50,FALSE),"—"),IF(A6="Pharmacists",IFERROR(VLOOKUP(CONCATENATE($D$6,$A$6,$B$6,$C$6),PHProfileData!$A$3:$BR$1868,48,FALSE),"—"),IF(A6="nurse practitioners",IFERROR(VLOOKUP(CONCATENATE($D$6,$A$6,$B$6,$C$6),NursProfileData!$A$2:$BZ$2066,52,FALSE),"—"),IF(A6="Registered nurses",IFERROR(VLOOKUP(CONCATENATE($D$6,$A$6,$B$6,$C$6),NursProfileData!$A$2:$BZ$2066,52,FALSE),"—"),IF(A6="Registered psychiatric nurses",IFERROR(VLOOKUP(CONCATENATE($D$6,$A$6,$B$6,$C$6),NursProfileData!$A$2:$BZ$2066,52,FALSE),"—"),IF(A6="Licensed practical nurses",IFERROR(VLOOKUP(CONCATENATE($D$6,$A$6,$B$6,$C$6),NursProfileData!$A$2:$BZ$2066,52,FALSE),"—"),"-")))))))))) -> 0.036407839
B24: 70+ | C24: =IF(A6="Family medicine physicians",IFERROR(VLOOKUP(CONCATENATE($D$6,$A$6,$B$6),Phyprofile!A3:AU464,18,FALSE),"—"),IF(A6="Specialists",IFERROR(VLOOKUP(CONCATENATE($D$6,$A$6,$B$6),Phyprofile!A3:AU464,18,FALSE),"—"),IF(A6="All physicians",IFERROR(VLOOKUP(CONCATENATE($D$6,$A$6,$B$6),Phyprofile!A3:AU464,18,FALSE),"—"),IF(A6="Occupational therapists",IFERROR(VLOOKUP(CONCATENATE($D$6,$A$6,$B$6,$C$6),OTProfileData!$A$2:$AR$1920,18,FALSE),"—"),IF(A6="Physiotherapists",IFERROR(VLOOKUP(CONCATENATE($D$6,$A$6,$B$6,$C$6),PTProfileData!$A$2:$BW$1802,18,FALSE),"—"),IF(A6="Pharmacists",IFERROR(VLOOKUP(CONCATENATE($D$6,$A$6,$B$6,$C$6),PHProfileData!$A$3:$AO$1868,18,FALSE),"—"),IF(A6="nurse practitioners",IFERROR(VLOOKUP(CONCATENATE($D$6,$A$6,$B$6,$C$6),NursProfileData!$A$2:$BZ$2066,18,FALSE),"—"),IF(A6="Registered nurses",IFERROR(VLOOKUP(CONCATENATE($D$6,$A$6,$B$6,$C$6),NursProfileData!$A$2:$BZ$2066,18,FALSE),"—"),IF(A6="Registered psychiatric nurses",IFERROR(VLOOKUP(CONCATENATE($D$6,$A$6,$B$6,$C$6),NursProfileData!$A$2:$BZ$2066,18,FALSE),"—"),IF(A6="Licensed practical nurses",IFERROR(VLOOKUP(CONCATENATE($D$6,$A$6,$B$6,$C$6),NursProfileData!$A$2:$BZ$2066,18,FALSE),"—"),"-")))))))))) -> 1828 | D24: =IF(A6="Family medicine physicians",IFERROR(VLOOKUP(CONCATENATE($D$6,$A$6,$B$6),Phyprofile!A3:AU464,39,FALSE),"—"),IF(A6="Specialists",IFERROR(VLOOKUP(CONCATENATE($D$6,$A$6,$B$6),Phyprofile!A3:AU464,39,FALSE),"—"),IF(A6="All physicians",IFERROR(VLOOKUP(CONCATENATE($D$6,$A$6,$B$6),Phyprofile!A3:AU464,39,FALSE),"—"),IF(A6="Occupational therapists",IFERROR(VLOOKUP(CONCATENATE($D$6,$A$6,$B$6,$C$6),OTProfileData!$A$2:$CB$1920,54,FALSE),"—"),IF(A6="Physiotherapists",IFERROR(VLOOKUP(CONCATENATE($D$6,$A$6,$B$6,$C$6),PTProfileData!$A$2:$BW$1802,51,FALSE),"—"),IF(A6="Pharmacists",IFERROR(VLOOKUP(CONCATENATE($D$6,$A$6,$B$6,$C$6),PHProfileData!$A$3:$BR$1868,49,FALSE),"—"),IF(A6="nurse practitioners",IFERROR(VLOOKUP(CONCATENATE($D$6,$A$6,$B$6,$C$6),NursProfileData!$A$2:$BZ$2066,53,FALSE),"—"),IF(A6="Registered nurses",IFERROR(VLOOKUP(CONCATENATE($D$6,$A$6,$B$6,$C$6),NursProfileData!$A$2:$BZ$2066,53,FALSE),"—"),IF(A6="Registered psychiatric nurses",IFERROR(VLOOKUP(CONCATENATE($D$6,$A$6,$B$6,$C$6),NursProfileData!$A$2:$BZ$2066,53,FALSE),"—"),IF(A6="Licensed practical nurses",IFERROR(VLOOKUP(CONCATENATE($D$6,$A$6,$B$6,$C$6),NursProfileData!$A$2:$BZ$2066,53,FALSE),"—"),"-")))))))))) -> 0.027077038
B25: Not stated | C25: =IF(A6="Family medicine physicians",IFERROR(VLOOKUP(CONCATENATE($D$6,$A$6,$B$6),Phyprofile!A3:AU464,20,FALSE),"—"),IF(A6="Specialists",IFERROR(VLOOKUP(CONCATENATE($D$6,$A$6,$B$6),Phyprofile!A3:AU464,20,FALSE),"—"),IF(A6="All physicians",IFERROR(VLOOKUP(CONCATENATE($D$6,$A$6,$B$6),Phyprofile!A3:AU464,20,FALSE),"—"),IF(A6="Occupational therapists",IFERROR(VLOOKUP(CONCATENATE($D$6,$A$6,$B$6,$C$6),OTProfileData!$A$2:$AR$1920,20,FALSE),"—"),IF(A6="Physiotherapists",IFERROR(VLOOKUP(CONCATENATE($D$6,$A$6,$B$6,$C$6),PTProfileData!$A$2:$BW$1802,20,FALSE),"—"),IF(A6="Pharmacists",IFERROR(VLOOKUP(CONCATENATE($D$6,$A$6,$B$6,$C$6),PHProfileData!$A$3:$AO$1868,20,FALSE),"—"),IF(A6="nurse practitioners",IFERROR(VLOOKUP(CONCATENATE($D$6,$A$6,$B$6,$C$6),NursProfileData!$A$2:$BZ$2066,20,FALSE),"—"),IF(A6="Registered nurses",IFERROR(VLOOKUP(CONCATENATE($D$6,$A$6,$B$6,$C$6),NursProfileData!$A$2:$BZ$2066,20,FALSE),"—"),IF(A6="Registered psychiatric nurses",IFERROR(VLOOKUP(CONCATENATE($D$6,$A$6,$B$6,$C$6),NursProfileData!$A$2:$BZ$2066,20,FALSE),"—"),IF(A6="Licensed practical nurses",IFERROR(VLOOKUP(CONCATENATE($D$6,$A$6,$B$6,$C$6),NursProfileData!$A$2:$BZ$2066,20,FALSE),"—"),"-")))))))))) -> 0 | D25: =IF(A6="Family medicine physicians",IFERROR(VLOOKUP(CONCATENATE($D$6,$A$6,$B$6),Phyprofile!A3:AU464,41,FALSE),"—"),IF(A6="Specialists",IFERROR(VLOOKUP(CONCATENATE($D$6,$A$6,$B$6),Phyprofile!A3:AU464,41,FALSE),"—"),IF(A6="All physicians",IFERROR(VLOOKUP(CONCATENATE($D$6,$A$6,$B$6),Phyprofile!A3:AU464,41,FALSE),"—"),IF(A6="Occupational therapists",IFERROR(VLOOKUP(CONCATENATE($D$6,$A$6,$B$6,$C$6),OTProfileData!$A$2:$CB$1920,56,FALSE),"—"),IF(A6="Physiotherapists",IFERROR(VLOOKUP(CONCATENATE($D$6,$A$6,$B$6,$C$6),PTProfileData!$A$2:$BW$1802,53,FALSE),"—"),IF(A6="Pharmacists",IFERROR(VLOOKUP(CONCATENATE($D$6,$A$6,$B$6,$C$6),PHProfileData!$A$3:$BR$1868,51,FALSE),"—"),IF(A6="nurse practitioners",IFERROR(VLOOKUP(CONCATENATE($D$6,$A$6,$B$6,$C$6),NursProfileData!$A$2:$BZ$2066,55,FALSE),"—"),IF(A6="Registered nurses",IFERROR(VLOOKUP(CONCATENATE($D$6,$A$6,$B$6,$C$6),NursProfileData!$A$2:$BZ$2066,55,FALSE),"—"),IF(A6="Registered psychiatric nurses",IFERROR(VLOOKUP(CONCATENATE($D$6,$A$6,$B$6,$C$6),NursProfileData!$A$2:$BZ$2066,55,FALSE),"—"),IF(A6="Licensed practical nurses",IFERROR(VLOOKUP(CONCATENATE($D$6,$A$6,$B$6,$C$6),NursProfileData!$A$2:$BZ$2066,55,FALSE),"—"),"-")))))))))) -> 0
A26: Country of Graduation | B26: Canadian educated | C26: =IF(A6="Family medicine physicians",IFERROR(VLOOKUP(CONCATENATE($D$6,$A$6,$B$6),Phyprofile!A3:AU464,21,FALSE),"—"),IF(A6="Specialists",IFERROR(VLOOKUP(CONCATENATE($D$6,$A$6,$B$6),Phyprofile!A3:AU464,21,FALSE),"—"),IF(A6="All physicians",IFERROR(VLOOKUP(CONCATENATE($D$6,$A$6,$B$6),Phyprofile!A3:AU464,21,FALSE),"—"),IF(A6="Occupational therapists",IFERROR(VLOOKUP(CONCATENATE($D$6,$A$6,$B$6,$C$6),OTProfileData!$A$2:$AR$1920,21,FALSE),"—"),IF(A6="Physiotherapists",IFERROR(VLOOKUP(CONCATENATE($D$6,$A$6,$B$6,$C$6),PTProfileData!$A$2:$BW$1802,21,FALSE),"—"),IF(A6="Pharmacists",IFERROR(VLOOKUP(CONCATENATE($D$6,$A$6,$B$6,$C$6),PHProfileData!$A$3:$AO$1868,21,FALSE),"—"),IF(A6="nurse practitioners",IFERROR(VLOOKUP(CONCATENATE($D$6,$A$6,$B$6,$C$6),NursProfileData!$A$2:$BZ$2066,21,FALSE),"—"),IF(A6="Registered nurses",IFERROR(VLOOKUP(CONCATENATE($D$6,$A$6,$B$6,$C$6),NursProfileData!$A$2:$BZ$2066,21,FALSE),"—"),IF(A6="Registered psychiatric nurses",IFERROR(VLOOKUP(CONCATENATE($D$6,$A$6,$B$6,$C$6),NursProfileData!$A$2:$BZ$2066,21,FALSE),"—"),IF(A6="Licensed practical nurses",IFERROR(VLOOKUP(CONCATENATE($D$6,$A$6,$B$6,$C$6),NursProfileData!$A$2:$BZ$2066,21,FALSE),"—"),"-")))))))))) -> 87066 | D26: =IF(A6="Family medicine physicians",IFERROR(VLOOKUP(CONCATENATE($D$6,$A$6,$B$6),Phyprofile!A3:AU464,42,FALSE),"—"),IF(A6="Specialists",IFERROR(VLOOKUP(CONCATENATE($D$6,$A$6,$B$6),Phyprofile!A3:AU464,42,FALSE),"—"),IF(A6="All physicians",IFERROR(VLOOKUP(CONCATENATE($D$6,$A$6,$B$6),Phyprofile!A3:AU464,42,FALSE),"—"),IF(A6="Occupational therapists",IFERROR(VLOOKUP(CONCATENATE($D$6,$A$6,$B$6,$C$6),OTProfileData!$A$2:$CB$1920,57,FALSE),"—"),IF(A6="Physiotherapists",IFERROR(VLOOKUP(CONCATENATE($D$6,$A$6,$B$6,$C$6),PTProfileData!$A$2:$BW$1802,54,FALSE),"—"),IF(A6="Pharmacists",IFERROR(VLOOKUP(CONCATENATE($D$6,$A$6,$B$6,$C$6),PHProfileData!$A$3:$BR$1868,52,FALSE),"—"),IF(A6="nurse practitioners",IFERROR(VLOOKUP(CONCATENATE($D$6,$A$6,$B$6,$C$6),NursProfileData!$A$2:$BZ$2066,56,FALSE),"—"),IF(A6="Registered nurses",IFERROR(VLOOKUP(CONCATENATE($D$6,$A$6,$B$6,$C$6),NursProfileData!$A$2:$BZ$2066,56,FALSE),"—"),IF(A6="Registered psychiatric nurses",IFERROR(VLOOKUP(CONCATENATE($D$6,$A$6,$B$6,$C$6),NursProfileData!$A$2:$BZ$2066,56,FALSE),"—"),IF(A6="Licensed practical nurses",IFERROR(VLOOKUP(CONCATENATE($D$6,$A$6,$B$6,$C$6),NursProfileData!$A$2:$BZ$2066,56,FALSE),"—"),"-")))))))))) -> 0.85695725
B27: Internationally educated | C27: =IF(A6="Family medicine physicians",IFERROR(VLOOKUP(CONCATENATE($D$6,$A$6,$B$6),Phyprofile!A3:AU464,22,FALSE),"—"),IF(A6="Specialists",IFERROR(VLOOKUP(CONCATENATE($D$6,$A$6,$B$6),Phyprofile!A3:AU464,22,FALSE),"—"),IF(A6="All physicians",IFERROR(VLOOKUP(CONCATENATE($D$6,$A$6,$B$6),Phyprofile!A3:AU464,22,FALSE),"—"),IF(A6="Occupational therapists",IFERROR(VLOOKUP(CONCATENATE($D$6,$A$6,$B$6,$C$6),OTProfileData!$A$2:$AR$1920,22,FALSE),"—"),IF(A6="Physiotherapists",IFERROR(VLOOKUP(CONCATENATE($D$6,$A$6,$B$6,$C$6),PTProfileData!$A$2:$BW$1802,22,FALSE),"—"),IF(A6="Pharmacists",IFERROR(VLOOKUP(CONCATENATE($D$6,$A$6,$B$6,$C$6),PHProfileData!$A$3:$AO$1868,22,FALSE),"—"),IF(A6="nurse practitioners",IFERROR(VLOOKUP(CONCATENATE($D$6,$A$6,$B$6,$C$6),NursProfileData!$A$2:$BZ$2066,22,FALSE),"—"),IF(A6="Registered nurses",IFERROR(VLOOKUP(CONCATENATE($D$6,$A$6,$B$6,$C$6),NursProfileData!$A$2:$BZ$2066,22,FALSE),"—"),IF(A6="Registered psychiatric nurses",IFERROR(VLOOKUP(CONCATENATE($D$6,$A$6,$B$6,$C$6),NursProfileData!$A$2:$BZ$2066,22,FALSE),"—"),IF(A6="Licensed practical nurses",IFERROR(VLOOKUP(CONCATENATE($D$6,$A$6,$B$6,$C$6),NursProfileData!$A$2:$BZ$2066,22,FALSE),"—"),"-")))))))))) -> 14529 | D27: =IF(A6="Family medicine physicians",IFERROR(VLOOKUP(CONCATENATE($D$6,$A$6,$B$6),Phyprofile!A3:AU464,43,FALSE),"—"),IF(A6="Specialists",IFERROR(VLOOKUP(CONCATENATE($D$6,$A$6,$B$6),Phyprofile!A3:AU464,43,FALSE),"—"),IF(A6="All physicians",IFERROR(VLOOKUP(CONCATENATE($D$6,$A$6,$B$6),Phyprofile!A3:AU464,43,FALSE),"—"),IF(A6="Occupational therapists",IFERROR(VLOOKUP(CONCATENATE($D$6,$A$6,$B$6,$C$6),OTProfileData!$A$2:$CB$1920,58,FALSE),"—"),IF(A6="Physiotherapists",IFERROR(VLOOKUP(CONCATENATE($D$6,$A$6,$B$6,$C$6),PTProfileData!$A$2:$BW$1802,55,FALSE),"—"),IF(A6="Pharmacists",IFERROR(VLOOKUP(CONCATENATE($D$6,$A$6,$B$6,$C$6),PHProfileData!$A$3:$BR$1868,53,FALSE),"—"),IF(A6="nurse practitioners",IFERROR(VLOOKUP(CONCATENATE($D$6,$A$6,$B$6,$C$6),NursProfileData!$A$2:$BZ$2066,57,FALSE),"—"),IF(A6="Registered nurses",IFERROR(VLOOKUP(CONCATENATE($D$6,$A$6,$B$6,$C$6),NursProfileData!$A$2:$BZ$2066,57,FALSE),"—"),IF(A6="Registered psychiatric nurses",IFERROR(VLOOKUP(CONCATENATE($D$6,$A$6,$B$6,$C$6),NursProfileData!$A$2:$BZ$2066,57,FALSE),"—"),IF(A6="Licensed practical nurses",IFERROR(VLOOKUP(CONCATENATE($D$6,$A$6,$B$6,$C$6),NursProfileData!$A$2:$BZ$2066,57,FALSE),"—"),"-")))))))))) -> 0.14300338
B28: Not stated | C28: =IF(A6="Family medicine physicians",IFERROR(VLOOKUP(CONCATENATE($D$6,$A$6,$B$6),Phyprofile!A3:AU464,23,FALSE),"—"),IF(A6="Specialists",IFERROR(VLOOKUP(CONCATENATE($D$6,$A$6,$B$6),Phyprofile!A3:AU464,23,FALSE),"—"),IF(A6="All physicians",IFERROR(VLOOKUP(CONCATENATE($D$6,$A$6,$B$6),Phyprofile!A3:AU464,23,FALSE),"—"),IF(A6="Occupational therapists",IFERROR(VLOOKUP(CONCATENATE($D$6,$A$6,$B$6,$C$6),OTProfileData!$A$2:$AR$1920,23,FALSE),"—"),IF(A6="Physiotherapists",IFERROR(VLOOKUP(CONCATENATE($D$6,$A$6,$B$6,$C$6),PTProfileData!$A$2:$BW$1802,23,FALSE),"—"),IF(A6="Pharmacists",IFERROR(VLOOKUP(CONCATENATE($D$6,$A$6,$B$6,$C$6),PHProfileData!$A$3:$AO$1868,23,FALSE),"—"),IF(A6="nurse practitioners",IFERROR(VLOOKUP(CONCATENATE($D$6,$A$6,$B$6,$C$6),NursProfileData!$A$2:$BZ$2066,23,FALSE),"—"),IF(A6="Registered nurses",IFERROR(VLOOKUP(CONCATENATE($D$6,$A$6,$B$6,$C$6),NursProfileData!$A$2:$BZ$2066,23,FALSE),"—"),IF(A6="Registered psychiatric nurses",IFERROR(VLOOKUP(CONCATENATE($D$6,$A$6,$B$6,$C$6),NursProfileData!$A$2:$BZ$2066,23,FALSE),"—"),IF(A6="Licensed practical nurses",IFERROR(VLOOKUP(CONCATENATE($D$6,$A$6,$B$6,$C$6),NursProfileData!$A$2:$BZ$2066,23,FALSE),"—"),"-")))))))))) -> 4 | D28: =IF(A6="Family medicine physicians",IFERROR(VLOOKUP(CONCATENATE($D$6,$A$6,$B$6),Phyprofile!A3:AU464,44,FALSE),"—"),IF(A6="Specialists",IFERROR(VLOOKUP(CONCATENATE($D$6,$A$6,$B$6),Phyprofile!A3:AU464,44,FALSE),"—"),IF(A6="All physicians",IFERROR(VLOOKUP(CONCATENATE($D$6,$A$6,$B$6),Phyprofile!A3:AU464,44,FALSE),"—"),IF(A6="Occupational therapists",IFERROR(VLOOKUP(CONCATENATE($D$6,$A$6,$B$6,$C$6),OTProfileData!$A$2:$CB$1920,59,FALSE),"—"),IF(A6="Physiotherapists",IFERROR(VLOOKUP(CONCATENATE($D$6,$A$6,$B$6,$C$6),PTProfileData!$A$2:$BW$1802,56,FALSE),"—"),IF(A6="Pharmacists",IFERROR(VLOOKUP(CONCATENATE($D$6,$A$6,$B$6,$C$6),PHProfileData!$A$3:$BR$1868,54,FALSE),"—"),IF(A6="nurse practitioners",IFERROR(VLOOKUP(CONCATENATE($D$6,$A$6,$B$6,$C$6),NursProfileData!$A$2:$BZ$2066,58,FALSE),"—"),IF(A6="Registered nurses",IFERROR(VLOOKUP(CONCATENATE($D$6,$A$6,$B$6,$C$6),NursProfileData!$A$2:$BZ$2066,58,FALSE),"—"),IF(A6="Registered psychiatric nurses",IFERROR(VLOOKUP(CONCATENATE($D$6,$A$6,$B$6,$C$6),NursProfileData!$A$2:$BZ$2066,58,FALSE),"—"),IF(A6="Licensed practical nurses",IFERROR(VLOOKUP(CONCATENATE($D$6,$A$6,$B$6,$C$6),NursProfileData!$A$2:$BZ$2066,58,FALSE),"—"),"-")))))))))) -> 3.9370466e-05
A29: =IF(A6="Family medicine physicians","—",IF(A6="Specialists","—",IF(A6="All physicians","—",IF(A6="Occupational therapists","Employment Status",IF(A6="Physiotherapists","Employment Status",IF(A6="Pharmacists","Employment Category",IF(A6="nurse practitioners","Employment Status",IF(A6="Registered nurses","Employment Status",IF(A6="Registered psychiatric nurses","Employment Status",IF(A6="Licensed practical nurses","Employment Status","-")))))))))) -> Employment Status | B29: =IF(A6="Family medicine physicians","—",IF(A6="Specialists","—",IF(A6="All physicians","—",IF(A6="Occupational therapists","Full-time",IF(A6="Physiotherapists","Full-time",IF(A6="Pharmacists","Permanent",IF(A6="Nurse practitioners","Full-time",IF(A6="Registered nurses","Full-time",IF(A6="Registered psychiatric nurses","Full-time",IF(A6="Licensed practical nurses","Full-time","—")))))))))) -> Full-time | C29: =IF(A6="Family medicine physicians","—",IF(A6="Specialists","—",IF(A6="All physicians","—",IF(A6="Occupational therapists",IFERROR(VLOOKUP(CONCATENATE($D$6,$A$6,$B$6,$C$6),OTProfileData!$A$2:$AR$1920,24,FALSE),"—"),IF(A6="Physiotherapists",IFERROR(VLOOKUP(CONCATENATE($D$6,$A$6,$B$6,$C$6),PTProfileData!$A$2:$BW$1802,24,FALSE),"—"),IF(A6="Pharmacists",IFERROR(VLOOKUP(CONCATENATE($D$6,$A$6,$B$6,$C$6),PHProfileData!$A$3:$AO$1868,24,FALSE),"—"),IF(A6="nurse practitioners",IFERROR(VLOOKUP(CONCATENATE($D$6,$A$6,$B$6,$C$6),NursProfileData!$A$2:$BZ$2066,24,FALSE),"—"),IF(A6="Registered nurses",IFERROR(VLOOKUP(CONCATENATE($D$6,$A$6,$B$6,$C$6),NursProfileData!$A$2:$BZ$2066,24,FALSE),"—"),IF(A6="Registered psychiatric nurses",IFERROR(VLOOKUP(CONCATENATE($D$6,$A$6,$B$6,$C$6),NursProfileData!$A$2:$BZ$2066,24,FALSE),"—"),IF(A6="Licensed practical nurses",IFERROR(VLOOKUP(CONCATENATE($D$6,$A$6,$B$6,$C$6),NursProfileData!$A$2:$BZ$2066,24,FALSE),"—"),"—")))))))))) -> 71775 | D29: =IF(A6="Family medicine physicians","—",IF(A6="Specialists","—",IF(A6="All physicians","—",IF(A6="Occupational therapists",IFERROR(VLOOKUP(CONCATENATE($D$6,$A$6,$B$6,$C$6),OTProfileData!$A$2:$CB$1920,60,FALSE),"—"),IF(A6="Physiotherapists",IFERROR(VLOOKUP(CONCATENATE($D$6,$A$6,$B$6,$C$6),PTProfileData!$A$2:$BW$1802,57,FALSE),"—"),IF(A6="Pharmacists",IFERROR(VLOOKUP(CONCATENATE($D$6,$A$6,$B$6,$C$6),PHProfileData!$A$3:$BR$1868,55,FALSE),"—"),IF(A6="nurse practitioners",IFERROR(VLOOKUP(CONCATENATE($D$6,$A$6,$B$6,$C$6),NursProfileData!$A$2:$BZ$2066,59,FALSE),"—"),IF(A6="Registered nurses",IFERROR(VLOOKUP(CONCATENATE($D$6,$A$6,$B$6,$C$6),NursProfileData!$A$2:$BZ$2066,59,FALSE),"—"),IF(A6="Registered psychiatric nurses",IFERROR(VLOOKUP(CONCATENATE($D$6,$A$6,$B$6,$C$6),NursProfileData!$A$2:$BZ$2066,59,FALSE),"—"),IF(A6="Licensed practical nurses",IFERROR(VLOOKUP(CONCATENATE($D$6,$A$6,$B$6,$C$6),NursProfileData!$A$2:$BZ$2066,59,FALSE),"—"),"—")))))))))) -> 0.7064538
B30: =IF(A6="Family medicine physicians","—",IF(A6="Specialists","—",IF(A6="All physicians","—",IF(A6="Occupational therapists","Part-time",IF(A6="Physiotherapists","Part-time",IF(A6="Pharmacists","Temporary",IF(A6="nurse practitioners","Part-time",IF(A6="Registered nurses","Part-time",IF(A6="Registered psychiatric nurses","Part-time",IF(A6="Licensed practical nurses","Part-time","—")))))))))) -> Part-time | C30: =IF(A6="Family medicine physicians","—",IF(A6="Specialists","—",IF(A6="All physicians","—",IF(A6="Occupational therapists",IFERROR(VLOOKUP(CONCATENATE($D$6,$A$6,$B$6,$C$6),OTProfileData!$A$2:$AR$1920,25,FALSE),"—"),IF(A6="Physiotherapists",IFERROR(VLOOKUP(CONCATENATE($D$6,$A$6,$B$6,$C$6),PTProfileData!$A$2:$BW$1802,25,FALSE),"—"),IF(A6="Pharmacists",IFERROR(VLOOKUP(CONCATENATE($D$6,$A$6,$B$6,$C$6),PHProfileData!$A$3:$AO$1868,25,FALSE),"—"),IF(A6="nurse practitioners",IFERROR(VLOOKUP(CONCATENATE($D$6,$A$6,$B$6,$C$6),NursProfileData!$A$2:$BZ$2066,25,FALSE),"—"),IF(A6="Registered nurses",IFERROR(VLOOKUP(CONCATENATE($D$6,$A$6,$B$6,$C$6),NursProfileData!$A$2:$BZ$2066,25,FALSE),"—"),IF(A6="Registered psychiatric nurses",IFERROR(VLOOKUP(CONCATENATE($D$6,$A$6,$B$6,$C$6),NursProfileData!$A$2:$BZ$2066,25,FALSE),"—"),IF(A6="Licensed practical nurses",IFERROR(VLOOKUP(CONCATENATE($D$6,$A$6,$B$6,$C$6),NursProfileData!$A$2:$BZ$2066,25,FALSE),"—"),"-")))))))))) -> 21636 | D30: =IF(A6="Family medicine physicians","—",IF(A6="Specialists","—",IF(A6="All physicians","—",IF(A6="Occupational therapists",IFERROR(VLOOKUP(CONCATENATE($D$6,$A$6,$B$6,$C$6),OTProfileData!$A$2:$CB$1920,61,FALSE),"—"),IF(A6="Physiotherapists",IFERROR(VLOOKUP(CONCATENATE($D$6,$A$6,$B$6,$C$6),PTProfileData!$A$2:$BW$1802,58,FALSE),"—"),IF(A6="Pharmacists",IFERROR(VLOOKUP(CONCATENATE($D$6,$A$6,$B$6,$C$6),PHProfileData!$A$3:$BR$1868,56,FALSE),"—"),IF(A6="nurse practitioners",IFERROR(VLOOKUP(CONCATENATE($D$6,$A$6,$B$6,$C$6),NursProfileData!$A$2:$BZ$2066,60,FALSE),"—"),IF(A6="Registered nurses",IFERROR(VLOOKUP(CONCATENATE($D$6,$A$6,$B$6,$C$6),NursProfileData!$A$2:$BZ$2066,60,FALSE),"—"),IF(A6="Registered psychiatric nurses",IFERROR(VLOOKUP(CONCATENATE($D$6,$A$6,$B$6,$C$6),NursProfileData!$A$2:$BZ$2066,60,FALSE),"—"),IF(A6="Licensed practical nurses",IFERROR(VLOOKUP(CONCATENATE($D$6,$A$6,$B$6,$C$6),NursProfileData!$A$2:$BZ$2066,60,FALSE),"—"),"-")))))))))) -> 0.21295485
B31: =IF(A6="Family medicine physicians","—",IF(A6="Specialists","—",IF(A6="All physicians","—",IF(A6="Occupational therapists","—",IF(A6="Physiotherapists","—",IF(A6="Pharmacists","Casual",IF(A6="nurse practitioners","Casual",IF(A6="Registered nurses","Casual",IF(A6="Registered psychiatric nurses","Casual",IF(A6="Licensed practical nurses","Casual","—")))))))))) -> Casual | C31: =IF(A6="Family medicine physicians","—",IF(A6="Specialists","—",IF(A6="All physicians","—",IF(A6="Occupational therapists","—",IF(A6="Physiotherapists","—",IF(A6="Pharmacists",IFERROR(VLOOKUP(CONCATENATE($D$6,$A$6,$B$6,$C$6),PHProfileData!$A$3:$AO$1868,26,FALSE),"—"),IF(A6="nurse practitioners",IFERROR(VLOOKUP(CONCATENATE($D$6,$A$6,$B$6,$C$6),NursProfileData!$A$2:$BZ$2066,26,FALSE),"—"),IF(A6="Registered nurses",IFERROR(VLOOKUP(CONCATENATE($D$6,$A$6,$B$6,$C$6),NursProfileData!$A$2:$BZ$2066,26,FALSE),"—"),IF(A6="Registered psychiatric nurses",IFERROR(VLOOKUP(CONCATENATE($D$6,$A$6,$B$6,$C$6),NursProfileData!$A$2:$BZ$2066,26,FALSE),"—"),IF(A6="Licensed practical nurses",IFERROR(VLOOKUP(CONCATENATE($D$6,$A$6,$B$6,$C$6),NursProfileData!$A$2:$BZ$2066,26,FALSE),"—"),"—")))))))))) -> 8188 | D31: =IF(A6="Family medicine physicians","—",IF(A6="Specialists","—",IF(A6="All physicians","—",IF(A6="Occupational therapists","—",IF(A6="Physiotherapists","—",IF(A6="Pharmacists",IFERROR(VLOOKUP(CONCATENATE($D$6,$A$6,$B$6,$C$6),PHProfileData!$A$3:$BR$1868,57,FALSE),"—"),IF(A6="nurse practitioners",IFERROR(VLOOKUP(CONCATENATE($D$6,$A$6,$B$6,$C$6),NursProfileData!$A$2:$BZ$2066,61,FALSE),"—"),IF(A6="Registered nurses",IFERROR(VLOOKUP(CONCATENATE($D$6,$A$6,$B$6,$C$6),NursProfileData!$A$2:$BZ$2066,61,FALSE),"—"),IF(A6="Registered psychiatric nurses",IFERROR(VLOOKUP(CONCATENATE($D$6,$A$6,$B$6,$C$6),NursProfileData!$A$2:$BZ$2066,61,FALSE),"—"),IF(A6="Licensed practical nurses",IFERROR(VLOOKUP(CONCATENATE($D$6,$A$6,$B$6,$C$6),NursProfileData!$A$2:$BZ$2066,61,FALSE),"—"),"-")))))))))) -> 0.080591344
B32: =IF(A6="Family medicine physicians","—",IF(A6="Specialists","—",IF(A6="All physicians","—",IF(A6="Occupational therapists","—",IF(A6="Physiotherapists","—",IF(A6="Pharmacists","Self-employed",IF(A6="Nurse practitioners","—",IF(A6="Registered nurses","—",IF(A6="Registered psychiatric nurses","—",IF(A6="Licensed practical nurses","—","—")))))))))) -> — | C32: =IF(A6="Family medicine physicians","—",IF(A6="Specialists","—",IF(A6="All physicians","—",IF(A6="Occupational therapists","—",IF(A6="Physiotherapists","—",IF(A6="Pharmacists",IFERROR(VLOOKUP(CONCATENATE($D$6,$A$6,$B$6,$C$6),PHProfileData!$A$3:$AO$1868,27,FALSE),"—"),IF(A6="nurse practitioners","—",IF(A6="Registered nurses","—",IF(A6="Registered psychiatric nurses","—",IF(A6="Licensed practical nurses","—")))))))))) -> — | D32: =IF(A6="Family medicine physicians","—",IF(A6="Specialists","—",IF(A6="All physicians","—",IF(A6="Occupational therapists","—",IF(A6="Physiotherapists","—",IF(A6="Pharmacists",IFERROR(VLOOKUP(CONCATENATE($D$6,$A$6,$B$6,$C$6),PHProfileData!$A$3:$BR$1868,58,FALSE),"—"),IF(A6="nurse practitioners","—",IF(A6="Registered nurses","—",IF(A6="Registered psychiatric nurses","—",IF(A6="Licensed practical nurses","—")))))))))) -> —
